{"name": "test_auth_valid_data", "status": "broken", "statusDetails": {"message": "TypeError: a bytes-like object is required, not 'NoneType'", "trace": "self = <auth.test_auth.TestAuth object at 0x00000215FE50B610>, app = <pages.application.Application object at 0x00000215FE5CF430>\n\n    @allure.feature(\"authorisation\")\n    @allure.story(\"проверка на ввод существующего пользователя\")\n    def test_auth_valid_data(self, app):\n        \"\"\"\n        Steps\n        1. Open main page\n        2. Auth with valid data\n        3. Check auth result\n        \"\"\"\n        app.open_auth_page()\n        data = AuthData(login=\"kudimovaks@yandex.ru\", password=\"Capita_123\")\n        app.login.auth(data)\n        with allure.step(\"Делаем скриншот\"):\n>           allure.attach(app.login.auth(data), name=\"Screenshot_valid_data\", attachment_type=AttachmentType.PNG)\n\ntests\\auth\\test_auth.py:22: \n_ _ _ _ _ _ _ _ _ _ _ _ _ _ _ _ _ _ _ _ _ _ _ _ _ _ _ _ _ _ _ _ _ _ _ _ _ _ _ _ _ _ _ _ _ _ _ _ _ _ _ _ _ _ _ _ _ _ _ _ _ _ _ _ _ _ _ _ _ _ _ _ _ _ _ _ _ _ _ _ _ _ _ _ _ _ _ _ _ _ _ _ _ _ _ _ _ _ _ _ _ _ _ _ _ _ _ _ _ _ _ _ _ _ _ _ _ \nc:\\users\\user\\appdata\\local\\programs\\python\\python39\\lib\\site-packages\\allure_commons\\_allure.py:179: in __call__\n    plugin_manager.hook.attach_data(body=body, name=name, attachment_type=attachment_type, extension=extension)\nc:\\users\\user\\appdata\\local\\programs\\python\\python39\\lib\\site-packages\\pluggy\\hooks.py:286: in __call__\n    return self._hookexec(self, self.get_hookimpls(), kwargs)\nc:\\users\\user\\appdata\\local\\programs\\python\\python39\\lib\\site-packages\\pluggy\\manager.py:93: in _hookexec\n    return self._inner_hookexec(hook, methods, kwargs)\nc:\\users\\user\\appdata\\local\\programs\\python\\python39\\lib\\site-packages\\pluggy\\manager.py:84: in <lambda>\n    self._inner_hookexec = lambda hook, methods, kwargs: hook.multicall(\nc:\\users\\user\\appdata\\local\\programs\\python\\python39\\lib\\site-packages\\allure_pytest\\listener.py:222: in attach_data\n    self.allure_logger.attach_data(uuid4(), body, name=name, attachment_type=attachment_type, extension=extension)\nc:\\users\\user\\appdata\\local\\programs\\python\\python39\\lib\\site-packages\\allure_commons\\reporter.py:119: in attach_data\n    plugin_manager.hook.report_attached_data(body=body, file_name=file_name)\nc:\\users\\user\\appdata\\local\\programs\\python\\python39\\lib\\site-packages\\pluggy\\hooks.py:286: in __call__\n    return self._hookexec(self, self.get_hookimpls(), kwargs)\nc:\\users\\user\\appdata\\local\\programs\\python\\python39\\lib\\site-packages\\pluggy\\manager.py:93: in _hookexec\n    return self._inner_hookexec(hook, methods, kwargs)\nc:\\users\\user\\appdata\\local\\programs\\python\\python39\\lib\\site-packages\\pluggy\\manager.py:84: in <lambda>\n    self._inner_hookexec = lambda hook, methods, kwargs: hook.multicall(\n_ _ _ _ _ _ _ _ _ _ _ _ _ _ _ _ _ _ _ _ _ _ _ _ _ _ _ _ _ _ _ _ _ _ _ _ _ _ _ _ _ _ _ _ _ _ _ _ _ _ _ _ _ _ _ _ _ _ _ _ _ _ _ _ _ _ _ _ _ _ _ _ _ _ _ _ _ _ _ _ _ _ _ _ _ _ _ _ _ _ _ _ _ _ _ _ _ _ _ _ _ _ _ _ _ _ _ _ _ _ _ _ _ _ _ _ _ \n\nself = <allure_commons.logger.AllureFileLogger object at 0x00000215FE4A17C0>, body = None, file_name = '9c86d871-b774-49b1-bb29-ee1a50828799-attachment.png'\n\n    @hookimpl\n    def report_attached_data(self, body, file_name):\n        destination = os.path.join(self._report_dir, file_name)\n        with open(destination, 'wb') as attached_file:\n            if isinstance(body, text_type):\n                attached_file.write(body.encode('utf-8'))\n            else:\n>               attached_file.write(body)\nE               TypeError: a bytes-like object is required, not 'NoneType'\n\nc:\\users\\user\\appdata\\local\\programs\\python\\python39\\lib\\site-packages\\allure_commons\\logger.py:62: TypeError"}, "description": "\n        Steps\n        1. Open main page\n        2. Auth with valid data\n        3. Check auth result\n        ", "steps": [{"name": "Делаем скриншот", "status": "broken", "statusDetails": {"message": "TypeError: a bytes-like object is required, not 'NoneType'\n", "trace": "  File \"D:\\Ksenia\\QA\\Innopolis\\Auto_QA_Python\\Lesson_34-35\\test_moodle_project\\tests\\auth\\test_auth.py\", line 22, in test_auth_valid_data\n    allure.attach(app.login.auth(data), name=\"Screenshot_valid_data\", attachment_type=AttachmentType.PNG)\n  File \"c:\\users\\user\\appdata\\local\\programs\\python\\python39\\lib\\site-packages\\allure_commons\\_allure.py\", line 179, in __call__\n    plugin_manager.hook.attach_data(body=body, name=name, attachment_type=attachment_type, extension=extension)\n  File \"c:\\users\\user\\appdata\\local\\programs\\python\\python39\\lib\\site-packages\\pluggy\\hooks.py\", line 286, in __call__\n    return self._hookexec(self, self.get_hookimpls(), kwargs)\n  File \"c:\\users\\user\\appdata\\local\\programs\\python\\python39\\lib\\site-packages\\pluggy\\manager.py\", line 93, in _hookexec\n    return self._inner_hookexec(hook, methods, kwargs)\n  File \"c:\\users\\user\\appdata\\local\\programs\\python\\python39\\lib\\site-packages\\pluggy\\manager.py\", line 84, in <lambda>\n    self._inner_hookexec = lambda hook, methods, kwargs: hook.multicall(\n  File \"c:\\users\\user\\appdata\\local\\programs\\python\\python39\\lib\\site-packages\\pluggy\\callers.py\", line 208, in _multicall\n    return outcome.get_result()\n  File \"c:\\users\\user\\appdata\\local\\programs\\python\\python39\\lib\\site-packages\\pluggy\\callers.py\", line 80, in get_result\n    raise ex[1].with_traceback(ex[2])\n  File \"c:\\users\\user\\appdata\\local\\programs\\python\\python39\\lib\\site-packages\\pluggy\\callers.py\", line 187, in _multicall\n    res = hook_impl.function(*args)\n  File \"c:\\users\\user\\appdata\\local\\programs\\python\\python39\\lib\\site-packages\\allure_pytest\\listener.py\", line 222, in attach_data\n    self.allure_logger.attach_data(uuid4(), body, name=name, attachment_type=attachment_type, extension=extension)\n  File \"c:\\users\\user\\appdata\\local\\programs\\python\\python39\\lib\\site-packages\\allure_commons\\reporter.py\", line 119, in attach_data\n    plugin_manager.hook.report_attached_data(body=body, file_name=file_name)\n  File \"c:\\users\\user\\appdata\\local\\programs\\python\\python39\\lib\\site-packages\\pluggy\\hooks.py\", line 286, in __call__\n    return self._hookexec(self, self.get_hookimpls(), kwargs)\n  File \"c:\\users\\user\\appdata\\local\\programs\\python\\python39\\lib\\site-packages\\pluggy\\manager.py\", line 93, in _hookexec\n    return self._inner_hookexec(hook, methods, kwargs)\n  File \"c:\\users\\user\\appdata\\local\\programs\\python\\python39\\lib\\site-packages\\pluggy\\manager.py\", line 84, in <lambda>\n    self._inner_hookexec = lambda hook, methods, kwargs: hook.multicall(\n  File \"c:\\users\\user\\appdata\\local\\programs\\python\\python39\\lib\\site-packages\\pluggy\\callers.py\", line 208, in _multicall\n    return outcome.get_result()\n  File \"c:\\users\\user\\appdata\\local\\programs\\python\\python39\\lib\\site-packages\\pluggy\\callers.py\", line 80, in get_result\n    raise ex[1].with_traceback(ex[2])\n  File \"c:\\users\\user\\appdata\\local\\programs\\python\\python39\\lib\\site-packages\\pluggy\\callers.py\", line 187, in _multicall\n    res = hook_impl.function(*args)\n  File \"c:\\users\\user\\appdata\\local\\programs\\python\\python39\\lib\\site-packages\\allure_commons\\logger.py\", line 62, in report_attached_data\n    attached_file.write(body)\n"}, "attachments": [{"name": "Screenshot_valid_data", "source": "9c86d871-b774-49b1-bb29-ee1a50828799-attachment.png", "type": "image/png"}], "start": 1630746381209, "stop": 1630746382965}], "attachments": [{"name": "log", "source": "d4cb3caa-7d9e-4388-9ad3-0166281257b6-attachment.txt", "type": "text/plain"}, {"name": "stderr", "source": "1014271e-7c23-424b-b0f9-0c09aaeb591e-attachment.txt", "type": "text/plain"}], "start": 1630746378979, "stop": 1630746382979, "uuid": "834f68d3-c12a-4ec1-9f50-1e752a3e8e8a", "historyId": "fcec89ebca5f6daf506231d5c1f7ecc2", "testCaseId": "6cea31328895eceec9c3b31b56935715", "fullName": "tests.auth.test_auth.TestAuth#test_auth_valid_data", "labels": [{"name": "story", "value": "проверка на ввод существующего пользователя"}, {"name": "feature", "value": "authorisation"}, {"name": "parentSuite", "value": "tests.auth"}, {"name": "suite", "value": "test_auth"}, {"name": "subSuite", "value": "TestAuth"}, {"name": "host", "value": "PC-kashpovski"}, {"name": "thread", "value": "31324-MainThread"}, {"name": "framework", "value": "pytest"}, {"name": "language", "value": "cpython3"}, {"name": "package", "value": "tests.auth.test_auth"}]}