{"name": "test_auth_invalid_data", "status": "broken", "statusDetails": {"message": "TypeError: a bytes-like object is required, not 'NoneType'", "trace": "self = <auth.test_auth.TestAuth object at 0x00000215FE750A30>, app = <pages.application.Application object at 0x00000215FE5CF430>\n\n    @allure.feature(\"authorisation\")\n    @allure.story(\"проверка на ввод несуществующего пользователя\")\n    def test_auth_invalid_data(self, app):\n        \"\"\"\n        Steps\n        1. Open main page\n        2. Auth with invalid data\n        3. Check auth result\n        \"\"\"\n        app.open_auth_page()\n        data = AuthData.random()\n        app.login.auth(data)\n        with allure.step(\"Делаем скриншот\"):\n>           allure.attach(app.login.auth(data), name=\"Screenshot_invalid_data\", attachment_type=AttachmentType.PNG)\n\ntests\\auth\\test_auth.py:38: \n_ _ _ _ _ _ _ _ _ _ _ _ _ _ _ _ _ _ _ _ _ _ _ _ _ _ _ _ _ _ _ _ _ _ _ _ _ _ _ _ _ _ _ _ _ _ _ _ _ _ _ _ _ _ _ _ _ _ _ _ _ _ _ _ _ _ _ _ _ _ _ _ _ _ _ _ _ _ _ _ _ _ _ _ _ _ _ _ _ _ _ _ _ _ _ _ _ _ _ _ _ _ _ _ _ _ _ _ _ _ _ _ _ _ _ _ _ \nc:\\users\\user\\appdata\\local\\programs\\python\\python39\\lib\\site-packages\\allure_commons\\_allure.py:179: in __call__\n    plugin_manager.hook.attach_data(body=body, name=name, attachment_type=attachment_type, extension=extension)\nc:\\users\\user\\appdata\\local\\programs\\python\\python39\\lib\\site-packages\\pluggy\\hooks.py:286: in __call__\n    return self._hookexec(self, self.get_hookimpls(), kwargs)\nc:\\users\\user\\appdata\\local\\programs\\python\\python39\\lib\\site-packages\\pluggy\\manager.py:93: in _hookexec\n    return self._inner_hookexec(hook, methods, kwargs)\nc:\\users\\user\\appdata\\local\\programs\\python\\python39\\lib\\site-packages\\pluggy\\manager.py:84: in <lambda>\n    self._inner_hookexec = lambda hook, methods, kwargs: hook.multicall(\nc:\\users\\user\\appdata\\local\\programs\\python\\python39\\lib\\site-packages\\allure_pytest\\listener.py:222: in attach_data\n    self.allure_logger.attach_data(uuid4(), body, name=name, attachment_type=attachment_type, extension=extension)\nc:\\users\\user\\appdata\\local\\programs\\python\\python39\\lib\\site-packages\\allure_commons\\reporter.py:119: in attach_data\n    plugin_manager.hook.report_attached_data(body=body, file_name=file_name)\nc:\\users\\user\\appdata\\local\\programs\\python\\python39\\lib\\site-packages\\pluggy\\hooks.py:286: in __call__\n    return self._hookexec(self, self.get_hookimpls(), kwargs)\nc:\\users\\user\\appdata\\local\\programs\\python\\python39\\lib\\site-packages\\pluggy\\manager.py:93: in _hookexec\n    return self._inner_hookexec(hook, methods, kwargs)\nc:\\users\\user\\appdata\\local\\programs\\python\\python39\\lib\\site-packages\\pluggy\\manager.py:84: in <lambda>\n    self._inner_hookexec = lambda hook, methods, kwargs: hook.multicall(\n_ _ _ _ _ _ _ _ _ _ _ _ _ _ _ _ _ _ _ _ _ _ _ _ _ _ _ _ _ _ _ _ _ _ _ _ _ _ _ _ _ _ _ _ _ _ _ _ _ _ _ _ _ _ _ _ _ _ _ _ _ _ _ _ _ _ _ _ _ _ _ _ _ _ _ _ _ _ _ _ _ _ _ _ _ _ _ _ _ _ _ _ _ _ _ _ _ _ _ _ _ _ _ _ _ _ _ _ _ _ _ _ _ _ _ _ _ \n\nself = <allure_commons.logger.AllureFileLogger object at 0x00000215FE4A17C0>, body = None, file_name = '7faf6531-67d0-4b8b-9480-5213fe167dd6-attachment.png'\n\n    @hookimpl\n    def report_attached_data(self, body, file_name):\n        destination = os.path.join(self._report_dir, file_name)\n        with open(destination, 'wb') as attached_file:\n            if isinstance(body, text_type):\n                attached_file.write(body.encode('utf-8'))\n            else:\n>               attached_file.write(body)\nE               TypeError: a bytes-like object is required, not 'NoneType'\n\nc:\\users\\user\\appdata\\local\\programs\\python\\python39\\lib\\site-packages\\allure_commons\\logger.py:62: TypeError"}, "description": "\n        Steps\n        1. Open main page\n        2. Auth with invalid data\n        3. Check auth result\n        ", "steps": [{"name": "Делаем скриншот", "status": "broken", "statusDetails": {"message": "TypeError: a bytes-like object is required, not 'NoneType'\n", "trace": "  File \"D:\\Ksenia\\QA\\Innopolis\\Auto_QA_Python\\Lesson_34-35\\test_moodle_project\\tests\\auth\\test_auth.py\", line 38, in test_auth_invalid_data\n    allure.attach(app.login.auth(data), name=\"Screenshot_invalid_data\", attachment_type=AttachmentType.PNG)\n  File \"c:\\users\\user\\appdata\\local\\programs\\python\\python39\\lib\\site-packages\\allure_commons\\_allure.py\", line 179, in __call__\n    plugin_manager.hook.attach_data(body=body, name=name, attachment_type=attachment_type, extension=extension)\n  File \"c:\\users\\user\\appdata\\local\\programs\\python\\python39\\lib\\site-packages\\pluggy\\hooks.py\", line 286, in __call__\n    return self._hookexec(self, self.get_hookimpls(), kwargs)\n  File \"c:\\users\\user\\appdata\\local\\programs\\python\\python39\\lib\\site-packages\\pluggy\\manager.py\", line 93, in _hookexec\n    return self._inner_hookexec(hook, methods, kwargs)\n  File \"c:\\users\\user\\appdata\\local\\programs\\python\\python39\\lib\\site-packages\\pluggy\\manager.py\", line 84, in <lambda>\n    self._inner_hookexec = lambda hook, methods, kwargs: hook.multicall(\n  File \"c:\\users\\user\\appdata\\local\\programs\\python\\python39\\lib\\site-packages\\pluggy\\callers.py\", line 208, in _multicall\n    return outcome.get_result()\n  File \"c:\\users\\user\\appdata\\local\\programs\\python\\python39\\lib\\site-packages\\pluggy\\callers.py\", line 80, in get_result\n    raise ex[1].with_traceback(ex[2])\n  File \"c:\\users\\user\\appdata\\local\\programs\\python\\python39\\lib\\site-packages\\pluggy\\callers.py\", line 187, in _multicall\n    res = hook_impl.function(*args)\n  File \"c:\\users\\user\\appdata\\local\\programs\\python\\python39\\lib\\site-packages\\allure_pytest\\listener.py\", line 222, in attach_data\n    self.allure_logger.attach_data(uuid4(), body, name=name, attachment_type=attachment_type, extension=extension)\n  File \"c:\\users\\user\\appdata\\local\\programs\\python\\python39\\lib\\site-packages\\allure_commons\\reporter.py\", line 119, in attach_data\n    plugin_manager.hook.report_attached_data(body=body, file_name=file_name)\n  File \"c:\\users\\user\\appdata\\local\\programs\\python\\python39\\lib\\site-packages\\pluggy\\hooks.py\", line 286, in __call__\n    return self._hookexec(self, self.get_hookimpls(), kwargs)\n  File \"c:\\users\\user\\appdata\\local\\programs\\python\\python39\\lib\\site-packages\\pluggy\\manager.py\", line 93, in _hookexec\n    return self._inner_hookexec(hook, methods, kwargs)\n  File \"c:\\users\\user\\appdata\\local\\programs\\python\\python39\\lib\\site-packages\\pluggy\\manager.py\", line 84, in <lambda>\n    self._inner_hookexec = lambda hook, methods, kwargs: hook.multicall(\n  File \"c:\\users\\user\\appdata\\local\\programs\\python\\python39\\lib\\site-packages\\pluggy\\callers.py\", line 208, in _multicall\n    return outcome.get_result()\n  File \"c:\\users\\user\\appdata\\local\\programs\\python\\python39\\lib\\site-packages\\pluggy\\callers.py\", line 80, in get_result\n    raise ex[1].with_traceback(ex[2])\n  File \"c:\\users\\user\\appdata\\local\\programs\\python\\python39\\lib\\site-packages\\pluggy\\callers.py\", line 187, in _multicall\n    res = hook_impl.function(*args)\n  File \"c:\\users\\user\\appdata\\local\\programs\\python\\python39\\lib\\site-packages\\allure_commons\\logger.py\", line 62, in report_attached_data\n    attached_file.write(body)\n"}, "attachments": [{"name": "Screenshot_invalid_data", "source": "7faf6531-67d0-4b8b-9480-5213fe167dd6-attachment.png", "type": "image/png"}], "start": 1630746384333, "stop": 1630746384748}], "attachments": [{"name": "log", "source": "43fdb16a-a3a4-4029-b68f-81f1abc018ea-attachment.txt", "type": "text/plain"}], "start": 1630746383292, "stop": 1630746384749, "uuid": "54b71689-4569-441f-a72f-ede8cc795119", "historyId": "695f55378f8fe30fa2f217e0f6c38726", "testCaseId": "3288b5f502ddd6e63bc2e3b025925971", "fullName": "tests.auth.test_auth.TestAuth#test_auth_invalid_data", "labels": [{"name": "story", "value": "проверка на ввод несуществующего пользователя"}, {"name": "feature", "value": "authorisation"}, {"name": "parentSuite", "value": "tests.auth"}, {"name": "suite", "value": "test_auth"}, {"name": "subSuite", "value": "TestAuth"}, {"name": "host", "value": "PC-kashpovski"}, {"name": "thread", "value": "31324-MainThread"}, {"name": "framework", "value": "pytest"}, {"name": "language", "value": "cpython3"}, {"name": "package", "value": "tests.auth.test_auth"}]}